{\rtf1\ansi\ansicpg1252\cocoartf2580
\cocoatextscaling0\cocoaplatform0{\fonttbl\f0\fnil\fcharset0 Menlo-Regular;\f1\fnil\fcharset0 Menlo-Bold;}
{\colortbl;\red255\green255\blue255;\red0\green0\blue0;\red0\green0\blue0;\red251\green2\blue7;
}
{\*\expandedcolortbl;;\csgray\c0;\cssrgb\c0\c0\c0;\cssrgb\c100000\c14913\c0;
}
\paperw11900\paperh16840\margl1440\margr1440\vieww19220\viewh14740\viewkind0
\pard\tx560\tx1120\tx1680\tx2240\tx2800\tx3360\tx3920\tx4480\tx5040\tx5600\tx6160\tx6720\pardirnatural\partightenfactor0

\f0\fs22 \cf2 \CocoaLigature0 Tried to catch connection error:\
\
# Set wait_on_rate_limit to True while connecting through Tweepy\
api = tweepy.API(auth, wait_on_rate_limit=True)\
\
def get_userids(user,  retry_count=0):\
    # Get user ids of followers as a list\
    # request for 5000 follower ids in one request --> 75K ids in every 15 minute window\
    userids = []\
    MAX_RETRIES = 5\
    try:\
        userids = api.get_follower_ids(user_id=user)\
    except ConnectionError as e:\
        print(e)\
        print("ConectionResetError happend, trying again...")\
        if retry_count == MAX_RETRIES:\
            raise e\
        time.sleep(5)\
        get_userids(user, retry_count + 1)\
    except tweepy.errors.Unauthorized as e:\
        print(user, e)\
        pass\
\
    print("N.o followers", len(userids))\
    return userids\
\
Not able to catch ConnectionError with:\
- except ConnectionError as e:\
- except ConnectionResetError as e:\
\
Error log:\
\
Traceback (most recent call last):\
  File "/Users/shamsi/anaconda3/envs/dlaalto/lib/python3.7/site-packages/urllib3/connectionpool.py", line 706, in urlopen\
    chunked=chunked,\
  File "/Users/shamsi/anaconda3/envs/dlaalto/lib/python3.7/site-packages/urllib3/connectionpool.py", line 445, in _make_request\
    six.raise_from(e, None)\
  File "<string>", line 3, in raise_from\
  File "/Users/shamsi/anaconda3/envs/dlaalto/lib/python3.7/site-packages/urllib3/connectionpool.py", line 440, in _make_request\
    httplib_response = conn.getresponse()\
  File "/Users/shamsi/anaconda3/envs/dlaalto/lib/python3.7/http/client.py", line 1373, in getresponse\
    response.begin()\
  File "/Users/shamsi/anaconda3/envs/dlaalto/lib/python3.7/http/client.py", line 319, in begin\
    version, status, reason = self._read_status()\
  File "/Users/shamsi/anaconda3/envs/dlaalto/lib/python3.7/http/client.py", line 280, in _read_status\
    line = str(self.fp.readline(_MAXLINE + 1), "iso-8859-1")\
  File "/Users/shamsi/anaconda3/envs/dlaalto/lib/python3.7/socket.py", line 589, in readinto\
    return self._sock.recv_into(b)\
  File "/Users/shamsi/anaconda3/envs/dlaalto/lib/python3.7/ssl.py", line 1071, in recv_into\
    return self.read(nbytes, buffer)\
  File "/Users/shamsi/anaconda3/envs/dlaalto/lib/python3.7/ssl.py", line 929, in read\
    return self._sslobj.read(len, buffer)\

\f1\b \cf3 \cb4 ConnectionResetError\cf2 : [Errno 54] Connection reset by peer
\f0\b0 \cb1 \
\
During handling of the above exception, another exception occurred:\
\
Traceback (most recent call last):\
  File "/Users/shamsi/anaconda3/envs/dlaalto/lib/python3.7/site-packages/requests/adapters.py", line 449, in send\
    timeout=timeout\
  File "/Users/shamsi/anaconda3/envs/dlaalto/lib/python3.7/site-packages/urllib3/connectionpool.py", line 756, in urlopen\
    method, url, error=e, _pool=self, _stacktrace=sys.exc_info()[2]\
  File "/Users/shamsi/anaconda3/envs/dlaalto/lib/python3.7/site-packages/urllib3/util/retry.py", line 532, in increment\
    raise six.reraise(type(error), error, _stacktrace)\
  File "/Users/shamsi/anaconda3/envs/dlaalto/lib/python3.7/site-packages/urllib3/packages/six.py", line 769, in reraise\
    raise value.with_traceback(tb)\
  File "/Users/shamsi/anaconda3/envs/dlaalto/lib/python3.7/site-packages/urllib3/connectionpool.py", line 706, in urlopen\
    chunked=chunked,\
  File "/Users/shamsi/anaconda3/envs/dlaalto/lib/python3.7/site-packages/urllib3/connectionpool.py", line 445, in _make_request\
    six.raise_from(e, None)\
  File "<string>", line 3, in raise_from\
  File "/Users/shamsi/anaconda3/envs/dlaalto/lib/python3.7/site-packages/urllib3/connectionpool.py", line 440, in _make_request\
    httplib_response = conn.getresponse()\
  File "/Users/shamsi/anaconda3/envs/dlaalto/lib/python3.7/http/client.py", line 1373, in getresponse\
    response.begin()\
  File "/Users/shamsi/anaconda3/envs/dlaalto/lib/python3.7/http/client.py", line 319, in begin\
    version, status, reason = self._read_status()\
  File "/Users/shamsi/anaconda3/envs/dlaalto/lib/python3.7/http/client.py", line 280, in _read_status\
    line = str(self.fp.readline(_MAXLINE + 1), "iso-8859-1")\
  File "/Users/shamsi/anaconda3/envs/dlaalto/lib/python3.7/socket.py", line 589, in readinto\
    return self._sock.recv_into(b)\
  File "/Users/shamsi/anaconda3/envs/dlaalto/lib/python3.7/ssl.py", line 1071, in recv_into\
    return self.read(nbytes, buffer)\
  File "/Users/shamsi/anaconda3/envs/dlaalto/lib/python3.7/ssl.py", line 929, in read\
    return self._sslobj.read(len, buffer)\

\f1\b \cf3 \cb4 urllib3.exceptions.ProtocolError: ('Connection aborted.', ConnectionResetError(54, 'Connection reset by peer'))
\f0\b0 \cf2 \cb1 \
\
During handling of the above exception, another exception occurred:\
\
Traceback (most recent call last):\
  File "/Users/shamsi/anaconda3/envs/dlaalto/lib/python3.7/site-packages/tweepy/api.py", line 219, in request\
    timeout=self.timeout, auth=auth, proxies=self.proxy\
  File "/Users/shamsi/anaconda3/envs/dlaalto/lib/python3.7/site-packages/requests/sessions.py", line 542, in request\
    resp = self.send(prep, **send_kwargs)\
  File "/Users/shamsi/anaconda3/envs/dlaalto/lib/python3.7/site-packages/requests/sessions.py", line 655, in send\
    r = adapter.send(request, **kwargs)\
  File "/Users/shamsi/anaconda3/envs/dlaalto/lib/python3.7/site-packages/requests/adapters.py", line 498, in send\
    raise ConnectionError(err, request=request)\

\f1\b \cb4 requests.exceptions.ConnectionError: ('Connection aborted.', ConnectionResetError(54, 'Connection reset by peer'))
\f0\b0 \cb1 \
\
During handling of the above exception, another exception occurred:\
\
Traceback (most recent call last):\
  File "<string>", line 1, in <module>\
  File "/Users/shamsi/Desktop/twitter/followers.py", line 95, in get_followers_followers\
    followers[user] = get_userids(user)\
  File "/Users/shamsi/Desktop/twitter/followers.py", line 42, in get_userids\
    userids = api.get_follower_ids(user_id=user)\
  File "/Users/shamsi/anaconda3/envs/dlaalto/lib/python3.7/site-packages/tweepy/api.py", line 33, in wrapper\
    return method(*args, **kwargs)\
  File "/Users/shamsi/anaconda3/envs/dlaalto/lib/python3.7/site-packages/tweepy/api.py", line 46, in wrapper\
    return method(*args, **kwargs)\
  File "/Users/shamsi/anaconda3/envs/dlaalto/lib/python3.7/site-packages/tweepy/api.py", line 2117, in get_follower_ids\
    ), **kwargs\
  File "/Users/shamsi/anaconda3/envs/dlaalto/lib/python3.7/site-packages/tweepy/api.py", line 222, in request\
    raise TweepyException(f'Failed to send request: \{e\}').with_traceback(sys.exc_info()[2])\
  File "/Users/shamsi/anaconda3/envs/dlaalto/lib/python3.7/site-packages/tweepy/api.py", line 219, in request\
    timeout=self.timeout, auth=auth, proxies=self.proxy\
  File "/Users/shamsi/anaconda3/envs/dlaalto/lib/python3.7/site-packages/requests/sessions.py", line 542, in request\
    resp = self.send(prep, **send_kwargs)\
  File "/Users/shamsi/anaconda3/envs/dlaalto/lib/python3.7/site-packages/requests/sessions.py", line 655, in send\
    r = adapter.send(request, **kwargs)\
  File "/Users/shamsi/anaconda3/envs/dlaalto/lib/python3.7/site-packages/requests/adapters.py", line 498, in send\
    raise ConnectionError(err, request=request)\
\cb4 tweepy.errors.TweepyException: Failed to send request: ('Connection aborted.', ConnectionResetError(54, 'Connection reset by peer'))\cb1 \
\
\
\
\
\
\
\
\
\
\
\
\
}